<robot name="arm_robot">

    <link name="base_link">
        <visual name="">
            <origin xyz="0.0 0.0 0.1" rpy="0.0 0.0 0.0"/>
            <geometry>
                <box size="0.4 0.4 0.2"/>
            </geometry>
            <material name="">
                <color rgba="1.0 0.0 0.0 1.0"/>
                <texture filename=""/>
            </material>
        </visual>
    </link>

    <link name="link1">
        <visual name="">
            <origin xyz="0.0 0.0 0.5" rpy="0.0 0.0 0.0"/>
            <geometry>
                <cylinder radius="0.15" length="1.0"/>
            </geometry>
            <material name="">
                <color rgba="1.0 0.0 0.0 1.0"/>
                <texture filename=""/>
            </material>
        </visual>
    </link>

    <link name="link2">
        <visual name="">
            <origin xyz="-0.5 0.0 0.0" rpy="0.0 0.0 0.0"/>
            <geometry>
                <box size="1 0.2 0.2"/>
            </geometry>
            <material name="">
                <color rgba="0.0 1.0 0.0 1.0"/>
                <texture filename=""/>
            </material>
        </visual>
    </link>

    <link name="link3">
        <visual name="">
            <origin xyz="-0.5 0.0 0.0" rpy="0.0 0.0 0.0"/>
            <geometry>
                <box size="1 0.2 0.2"/>
            </geometry>
            <material name="">
                <color rgba="0.0 0.0 1.0 1.0"/>
                <texture filename=""/>
            </material>
        </visual>
    </link>


    <joint name="joint1" type="revolute">
        <parent link="base_link"/>
        <child link="link1"/>
        <axis xyz="0 0 -1"/>
        <limit lower="-3.14159" upper="3.14159" velocity="50.0" effort="1000.0"/>
        <origin xyz="0 0 0.2" rpy="0 0 0"/>
    </joint>

    <joint name="joint2" type="revolute">
        <parent link="link1"/>
        <child link="link2"/>
        <axis xyz="0 -1 0"/>
        <limit lower="-3.14159" upper="3.14159" velocity="50.0" effort="1000.0"/>
        <origin xyz="0 0 1" rpy="0 0 0"/>
    </joint>

    <joint name="joint3" type="revolute">
        <parent link="link2"/>
        <child link="link3"/>
        <axis xyz="0 -1 0"/>
        <limit lower="-3.14159" upper="3.14159" velocity="50.0" effort="1000.0"/>
        <origin xyz="-1 0 0" rpy="0 0 0"/>
    </joint>
    
</robot>